K [Create ( or update ) PostgreSQL Server] ****************************************************************
An exception occurred during task execution. To see the full traceback, use -vvv. The error was: NameError: global name 'PostgreSQLManagementClient' is not defined
fatal: [127.0.0.1]: FAILED! => {"changed": false, "module_stderr": "Traceback (most recent call last):\n  File \"/tmp/ansible_jKH2PO/ansible_module_azure_rm_postgresqlserver.py\", line 365, in <module>\n    main()\n  File \"/tmp/ansible_jKH2PO/ansible_module_azure_rm_postgresqlserver.py\", line 362, in main\n    AzureRMServers()\n  File \"/tmp/ansible_jKH2PO/ansible_module_azure_rm_postgresqlserver.py\", line 199, in __init__\n    supports_tags=False)\n  File \"/tmp/ansible_jKH2PO/ansible_modlib.zip/ansible/module_utils/azure_rm_common.py\", line 345, in __init__\n  File \"/tmp/ansible_jKH2PO/ansible_module_azure_rm_postgresqlserver.py\", line 234, in exec_module\n    self.mgmt_client = self.get_mgmt_svc_client(PostgreSQLManagementClient,\nNameError: global name 'PostgreSQLManagementClient' is not defined\n", "module_stdout": "", "msg": "MODULE FAILURE", "rc": 1}
	to retry, use: --limit @/home/fred/task/38431.retry

PLAY RECAP ***************************************************************************************************
127.0.0.1                  : ok=2    changed=0    unreachable=0    failed=1  

azure-mgmt-rdbms==0.1.0 / 0.2.0rc1


PLAY [For postgresqlserver try] ******************************************************************************

TASK [Gathering Facts] ***************************************************************************************
ok: [127.0.0.1]

TASK [Create resource group] *********************************************************************************
ok: [127.0.0.1]

TASK [Create ( or update ) PostgreSQL Server] ****************************************************************
 [WARNING]: Azure API profile latest does not define an entry for PostgreSQLManagementClient

ok: [127.0.0.1]

PLAY RECAP ***************************************************************************************************
127.0.0.1                  : ok=3    changed=0    unreachable=0    failed=0   
#################################0.3.1#############################
TASK [Create ( or update ) PostgreSQL Server] ****************************************************************
 [WARNING]: Azure API profile latest does not define an entry for PostgreSQLManagementClient

fatal: [127.0.0.1]: FAILED! => {"changed": false, "msg": "Error creating the PostgreSQL Server instance: Azure Error: InvalidEditionSloCombination\nMessage: The edition Basic does not support the service objective PGSQLS100"}
	to retry, use: --limit @/home/fred/task/38431/38431.retry

PLAY RECAP ***************************************************************************************************
127.0.0.1                  : ok=2    changed=0    unreachable=0    failed=1   

###########################1.1.1###################################
TASK [Create ( or update ) PostgreSQL Server] ****************************************************************
fatal: [127.0.0.1]: FAILED! => {"changed": false, "module_stderr": "No handlers could be found for logger \"msrestazure.azure_active_directory\"\nTraceback (most recent call last):\n  File \"/tmp/ansible_ZZnhFn/ansible_module_azure_rm_postgresqlserver.py\", line 365, in <module>\n    main()\n  File \"/tmp/ansible_ZZnhFn/ansible_module_azure_rm_postgresqlserver.py\", line 362, in main\n    AzureRMServers()\n  File \"/tmp/ansible_ZZnhFn/ansible_module_azure_rm_postgresqlserver.py\", line 199, in __init__\n    supports_tags=False)\n  File \"/tmp/ansible_ZZnhFn/ansible_modlib.zip/ansible/module_utils/azure_rm_common.py\", line 345, in __init__\n  File \"/tmp/ansible_ZZnhFn/ansible_module_azure_rm_postgresqlserver.py\", line 265, in exec_module\n    response = self.create_update_postgresqlserver()\n  File \"/tmp/ansible_ZZnhFn/ansible_module_azure_rm_postgresqlserver.py\", line 320, in create_update_postgresqlserver\n    return response.as_dict()\nAttributeError: 'LROPoller' object has no attribute 'as_dict'\n", "module_stdout": "", "msg": "MODULE FAILURE", "rc": 1}
	to retry, use: --limit @/home/fred/task/38431/38431.retry

PLAY RECAP ***************************************************************************************************
127.0.0.1                  : ok=2    changed=0    unreachable=0    failed=1   
