
TASK [create virtual network] **************************************************
An exception occurred during task execution. To see the full traceback, use -vvv. The error was: ValueError: Cannot use api-version and profile parameters at the same time
fatal: [localhost]: FAILED! => {"changed": false, "module_stderr": "Traceback (most recent call last):\n  File \"/tmp/ansible_OBpsPv/ansible_module_azure_rm_virtualnetwork.py\", line 352, in <module>\n    main()\n  File \"/tmp/ansible_OBpsPv/ansible_module_azure_rm_virtualnetwork.py\", line 349, in main\n    AzureRMVirtualNetwork()\n  File \"/tmp/ansible_OBpsPv/ansible_module_azure_rm_virtualnetwork.py\", line 205, in __init__\n    supports_check_mode=True)\n  File \"/tmp/ansible_OBpsPv/ansible_modlib.zip/ansible/module_utils/azure_rm_common.py\", line 345, in __init__\n  File \"/tmp/ansible_OBpsPv/ansible_module_azure_rm_virtualnetwork.py\", line 232, in exec_module\n    vnet = self.network_client.virtual_networks.get(self.resource_group, self.name)\n  File \"/tmp/ansible_OBpsPv/ansible_modlib.zip/ansible/module_utils/azure_rm_common.py\", line 889, in network_client\n  File \"/tmp/ansible_OBpsPv/ansible_modlib.zip/ansible/module_utils/azure_rm_common.py\", line 843, in get_mgmt_svc_client\n  File \"/usr/lib/python2.7/site-packages/azure/mgmt/network/network_management_client.py\", line 98, in __init__\n    profile=profile\n  File \"/usr/lib/python2.7/site-packages/azure/profiles/multiapiclient.py\", line 47, in __init__\n    raise ValueError(\"Cannot use api-version and profile parameters at the same time\")\nValueError: Cannot use api-version and profile parameters at the same time\n", "module_stdout": "", "msg": "MODULE FAILURE", "rc": 1}
	to retry, use: --limit @/home/azureuser/centos.retry

PLAY RECAP *********************************************************************
localhost                  : ok=3    changed=2    unreachable=0    failed=1  
